<?xml version="1.0"?>
<robot name="my_robot">

   <!-- Cac lien ket va khop noi duoc khai bao o day-->
   
   <link name="base_link">
   </link>
   
   <link name="chassis">
     <visual>
       <geometry>
         <box size="0.4 0.4 0.1"/>
       </geometry>
     </visual>
   </link>
   
   <joint name="chassis_joint" type="fixed">
      <parent link="base_link"/>
      <child link="chassis"/> 
   </joint>
   
   <!--color-->
   <material name="blue">
      <color rgba="0 0 0.8 1"/>
   </material>
   
   <material name="green">
    <color rgba="0 0.8 0. 1"/>
  </material>
   
   <!--front wheel-->
   <link name="front_wheel_right">
      <visual>
         <geometry>
            <cylinder length="0.04" radius="0.06"/>
         </geometry>
         <material name="blue"/>
      </visual>
   </link>
   
   <joint name="front_wheel_right_joint" type="continuous">
      <parent link="chassis"/>
      <child link="front_wheel_right"/>
      <origin xyz="0.2 -0.225 0" rpy="1.5707 0 0"/>
      <axis xyz="0 0 -1"/>
   </joint>
   
   <link name="front_wheel_left">
      <visual>
         <geometry>
            <cylinder length="0.04" radius="0.06"/>
         </geometry>
         <material name="blue"/>
      </visual>
   </link>
   
   <joint name="front_wheel_left_joint" type="continuous">
      <parent link="chassis"/>
      <child link="front_wheel_left"/>
      <origin xyz="0.2 0.225 0" rpy="-1.5707 0 0"/>
      <axis xyz="0 0 1"/>
   </joint>
   
   <!--rear wheel-->
      <link name="rear_wheel_right">
      <visual>
         <geometry>
            <cylinder length="0.04" radius="0.06"/>
         </geometry>
         <material name="blue"/>
      </visual>
   </link>
   
   <joint name="rear_wheel_right_joint" type="continuous">
      <parent link="chassis"/>
      <child link="rear_wheel_right"/>
      <origin xyz="-0.2 -0.225 0" rpy="1.5707 0 0"/>
      <axis xyz="0 0 -1"/>
   </joint>
   
   <link name="rear_wheel_left">
      <visual>
         <geometry>
            <cylinder length="0.04" radius="0.06"/>
         </geometry>
         <material name="blue"/>
      </visual>
   </link>
   
   <joint name="rear_wheel_left_joint" type="continuous">
      <parent link="chassis"/>
      <child link="rear_wheel_left"/>
      <origin xyz="-0.2 0.225 0" rpy="-1.5707 0 0"/>
      <axis xyz="0 0 1"/>
   </joint>
   
   <!--head box-->
    <link name="head">
     <visual>
       <geometry>
         <box size="0.12 0.12 0.12"/>
       </geometry>
       <material name="green"/>
     </visual>
   </link>
   
   <joint name="head_joint" type="fixed">
      <parent link="chassis"/>
      <child link="head"/> 
      <origin xyz="0.1 0 0.05" rpy="0 0 0"/>
   </joint>
   
    <!--gun-->
    <link name="gun">
     <visual>
       <geometry>
         <cylinder length="0.2" radius="0.02"/>
       </geometry>
       <material name="blue"/>
     </visual>
   </link>
   
   <joint name="gun_joint" type="fixed">
      <parent link="head"/>
      <child link="gun"/> 
      <origin xyz="0.1 0 0.03" rpy="0 1.5707 0"/>
   </joint>
   
</robot>
